<?xml version="1.0" ?>
<!-- =================================================================================== -->
<!-- |    This document was autogenerated by xacro from glados.xacro                   | -->
<!-- |    EDITING THIS FILE BY HAND IS NOT RECOMMENDED                                 | -->
<!-- =================================================================================== -->
<!-- Glados -->
<robot name="Glados" xmlns:xacro="http://www.ros.org/wiki/xacro">
  <material name="blue">
    <color rgba="0 0 .8 1"/>
  </material>
  <material name="black">
    <color rgba="0 0 0 1"/>
  </material>
  <material name="white">
    <color rgba="1 1 1 1"/>
  </material>
  <link name="base_link">
    <collision>
      <geometry>
        <box size="1.3 0.08 0.2"/>
      </geometry>
      <origin rpy="0 0 0" xyz="0 0 0.1"/>
    </collision>
    <visual>
      <geometry>
        <box size="1.3 0.08 0.2"/>
      </geometry>
      <origin rpy="0 0 0" xyz="0 0 0.1"/>
      <material name="blue"/>
    </visual>
  </link>
  <link name="front_part">
    <visual>
      <geometry>
        <box size="0.1 0.47 0.11"/>
      </geometry>
      <origin rpy="0 0 0" xyz="0 0 0.1"/>
      <material name="blue"/>
    </visual>
    <inertial>
      <origin rpy="0 0 0" xyz="0 0 0.1"/>
      <mass value="10"/>
      <inertia ixx="0.0386666666667" ixy="0.0" ixz="0.0" iyy="1.44166666667" iyz="0.0" izz="1.41366666667"/>
    </inertial>
  </link>
  <link name="back_part">
    <visual>
      <geometry>
        <box size="0.1 0.47 0.11"/>
      </geometry>
      <origin rpy="0 0 0" xyz="0 0 0.1"/>
      <material name="blue"/>
    </visual>
    <inertial>
      <origin rpy="0 0 0" xyz="0 0 0.1"/>
      <mass value="10"/>
      <inertia ixx="0.0386666666667" ixy="0.0" ixz="0.0" iyy="1.44166666667" iyz="0.0" izz="1.41366666667"/>
    </inertial>
  </link>
  <link name="left_front_wheel">
    <collision>
      <geometry>
        <cylinder length="0.058" radius="0.1"/>
      </geometry>
      <origin rpy="1.57079632679 0 0 "/>
      <material name="black"/>
    </collision>
    <visual>
      <geometry>
        <cylinder length="0.058" radius="0.1"/>
      </geometry>
      <origin rpy="1.57079632679 0 0 "/>
      <material name="black"/>
    </visual>
    <inertial>
      <origin rpy="0 0 0" xyz="0 0 0"/>
      <mass value="1"/>
      <inertia ixx="0.000530333333333" ixy="0.00" ixz="0.00" iyy="0.05" iyz="0.00" izz="0.000530333333333"/>
    </inertial>
  </link>
  <link name="right_front_wheel">
    <collision>
      <geometry>
        <cylinder length="0.058" radius="0.1"/>
      </geometry>
      <origin rpy="1.57079632679 0 0 "/>
      <material name="black"/>
    </collision>
    <visual>
      <geometry>
        <cylinder length="0.058" radius="0.1"/>
      </geometry>
      <origin rpy="1.57079632679 0 0 "/>
      <material name="black"/>
    </visual>
    <inertial>
      <origin rpy="0 0 0" xyz="0 0 0"/>
      <mass value="1"/>
      <inertia ixx="0.000530333333333" ixy="0.00" ixz="0.00" iyy="0.05" iyz="0.00" izz="0.000530333333333"/>
    </inertial>
  </link>
  
--&gt;


  <link name="right_back_wheel">
    <collision>
      <geometry>
        <cylinder length="0.058" radius="0.1"/>
      </geometry>
      <origin rpy="1.57079632679 0 0 "/>
      <material name="black"/>
    </collision>
    <visual>
      <geometry>
        <cylinder length="0.058" radius="0.1"/>
      </geometry>
      <origin rpy="1.57079632679 0 0 "/>
      <material name="black"/>
    </visual>
    <inertial>
      <origin rpy="0 0 0" xyz="0 0 0"/>
      <mass value="1"/>
      <inertia ixx="0.000530333333333" ixy="0.00" ixz="0.00" iyy="0.05" iyz="0.00" izz="0.000530333333333"/>
    </inertial>
  </link>
  <link name="left_back_wheel">
    <collision>
      <geometry>
        <cylinder length="0.058" radius="0.1"/>
      </geometry>
      <origin rpy="1.57079632679 0 0 "/>
      <material name="black"/>
    </collision>
    <visual>
      <geometry>
        <cylinder length="0.058" radius="0.1"/>
      </geometry>
      <origin rpy="1.57079632679 0 0 "/>
      <material name="black"/>
    </visual>
    <inertial>
      <origin rpy="0 0 0" xyz="0 0 0"/>
      <mass value="1"/>
      <inertia ixx="0.000530333333333" ixy="0.00" ixz="0.00" iyy="0.05" iyz="0.00" izz="0.000530333333333"/>
    </inertial>
  </link>
  <joint name="base_to_front_part" type="continuous">
    <axis rpy="0 0 0" xyz="0 0 1"/>
    <parent link="base_link"/>
    <child link="front_part"/>
    <origin xyz="0.406 0 0"/>
    <dynamics damping="0.0"/>
  </joint>
  <joint name="base_to_back_part" type="continuous">
    <axis rpy="0 0 0" xyz="0 0 1"/>
    <parent link="base_link"/>
    <child link="back_part"/>
    <origin xyz="-0.406 0 0"/>
    <dynamics damping="0.0"/>
  </joint>
  <joint name="front_part_to_left_front_wheel" type="continuous">
    <axis rpy="0 0 0" xyz="0 1 0"/>
    <parent link="front_part"/>
    <child link="left_front_wheel"/>
    <origin xyz="0.0 0.2 0"/>
    <dynamics damping="0.0"/>
  </joint>
  <joint name="back_part_to_left_back_wheel" type="continuous">
    <axis rpy="0 0 0" xyz="0 1 0"/>
    <parent link="back_part"/>
    <child link="left_back_wheel"/>
    <origin xyz="0.0 0.2 0"/>
    <dynamics damping="0.0"/>
  </joint>
  <joint name="front_part_to_right_front_wheel" type="continuous">
    <axis rpy="0 0 0" xyz="0 1 0"/>
    <parent link="front_part"/>
    <child link="right_front_wheel"/>
    <origin xyz="0.0 -0.2 0"/>
    <dynamics damping="0.0"/>
  </joint>
  <joint name="back_part_to_right_back_wheel" type="continuous">
    <axis rpy="0 0 0" xyz="0 1 0"/>
    <parent link="back_part"/>
    <child link="right_back_wheel"/>
    <origin xyz="0.0 -0.2 0"/>
    <dynamics damping="0.0"/>
  </joint>
  <!--Transmission  -->
  <transmission name="left_front_transmission">
    <type>transmission_interface/SimpleTransmission</type>
    <joint name="front_part_to_left_front_wheel">
      <hardwareInterface>VelocityJointInterface</hardwareInterface>
    </joint>
    <actuator name="motor1">
      <mechanicalReduction>1</mechanicalReduction>
    </actuator>
  </transmission>
  <transmission name="left_back_transmission">
    <type>transmission_interface/SimpleTransmission</type>
    <joint name="back_part_to_left_back_wheel">
      <hardwareInterface>VelocityJointInterface</hardwareInterface>
    </joint>
    <actuator name="motor3">
      <mechanicalReduction>1</mechanicalReduction>
    </actuator>
  </transmission>
  <transmission name="right_front_transmission">
    <type>transmission_interface/SimpleTransmission</type>
    <joint name="front_part_to_right_front_wheel">
      <hardwareInterface>VelocityJointInterface</hardwareInterface>
    </joint>
    <actuator name="motor2">
      <mechanicalReduction>1</mechanicalReduction>
    </actuator>
  </transmission>
  <transmission name="right_back_transmission">
    <type>transmission_interface/SimpleTransmission</type>
    <joint name="back_part_to_right_back_wheel">
      <hardwareInterface>VelocityJointInterface</hardwareInterface>
    </joint>
    <actuator name="motor4">
      <mechanicalReduction>1</mechanicalReduction>
    </actuator>
  </transmission>
</robot>

